Traceback (most recent call last):
  File "C:\Users\User\anaconda3\lib\site-packages\jupyter_cache\executors\utils.py", line 51, in single_nb_execution
    executenb(
  File "C:\Users\User\anaconda3\lib\site-packages\nbclient\client.py", line 1204, in execute
    return NotebookClient(nb=nb, resources=resources, km=km, **kwargs).execute()
  File "C:\Users\User\anaconda3\lib\site-packages\nbclient\util.py", line 84, in wrapped
    return just_run(coro(*args, **kwargs))
  File "C:\Users\User\anaconda3\lib\site-packages\nbclient\util.py", line 62, in just_run
    return loop.run_until_complete(coro)
  File "C:\Users\User\anaconda3\lib\asyncio\base_events.py", line 647, in run_until_complete
    return future.result()
  File "C:\Users\User\anaconda3\lib\site-packages\nbclient\client.py", line 663, in async_execute
    await self.async_execute_cell(
  File "C:\Users\User\anaconda3\lib\site-packages\nbclient\client.py", line 965, in async_execute_cell
    await self._check_raise_for_error(cell, cell_index, exec_reply)
  File "C:\Users\User\anaconda3\lib\site-packages\nbclient\client.py", line 862, in _check_raise_for_error
    raise CellExecutionError.from_cell_and_msg(cell, exec_reply_content)
nbclient.exceptions.CellExecutionError: An error occurred while executing the following cell:
------------------
G4.optimal_minimal_adj_set("D", "Y", [], ["X"])
------------------

[1;31m---------------------------------------------------------------------------[0m
[1;31mNoAdjException[0m                            Traceback (most recent call last)
Input [1;32mIn [8][0m, in [0;36m<cell line: 1>[1;34m()[0m
[1;32m----> 1[0m [43mG4[49m[38;5;241;43m.[39;49m[43moptimal_minimal_adj_set[49m[43m([49m[38;5;124;43m"[39;49m[38;5;124;43mD[39;49m[38;5;124;43m"[39;49m[43m,[49m[43m [49m[38;5;124;43m"[39;49m[38;5;124;43mY[39;49m[38;5;124;43m"[39;49m[43m,[49m[43m [49m[43m[[49m[43m][49m[43m,[49m[43m [49m[43m[[49m[38;5;124;43m"[39;49m[38;5;124;43mX[39;49m[38;5;124;43m"[39;49m[43m][49m[43m)[49m

File [1;32m~\anaconda3\lib\site-packages\optimaladj\CausalGraph.py:393[0m, in [0;36mCausalGraph.optimal_minimal_adj_set[1;34m(self, treatment, outcome, L, N)[0m
[0;32m    390[0m H1 [38;5;241m=[39m [38;5;28mself[39m[38;5;241m.[39mbuild_H1(treatment, outcome, L, N)
[0;32m    392[0m [38;5;28;01mif[39;00m treatment [38;5;129;01min[39;00m H1[38;5;241m.[39mneighbors(outcome):
[1;32m--> 393[0m     [38;5;28;01mraise[39;00m NoAdjException(EXCEPTION_NO_ADJ)
[0;32m    394[0m [38;5;28;01melse[39;00m:
[0;32m    395[0m     optimal_minimal [38;5;241m=[39m [38;5;28mself[39m[38;5;241m.[39munblocked(
[0;32m    396[0m         H1, treatment, nx[38;5;241m.[39mnode_boundary(H1, [38;5;28mset[39m([outcome]))
[0;32m    397[0m     )

[1;31mNoAdjException[0m: An adjustment set formed by observable variables does not exist
NoAdjException: An adjustment set formed by observable variables does not exist

