Traceback (most recent call last):
  File "C:\Users\User\anaconda3\lib\site-packages\jupyter_cache\executors\utils.py", line 51, in single_nb_execution
    executenb(
  File "C:\Users\User\anaconda3\lib\site-packages\nbclient\client.py", line 1204, in execute
    return NotebookClient(nb=nb, resources=resources, km=km, **kwargs).execute()
  File "C:\Users\User\anaconda3\lib\site-packages\nbclient\util.py", line 84, in wrapped
    return just_run(coro(*args, **kwargs))
  File "C:\Users\User\anaconda3\lib\site-packages\nbclient\util.py", line 62, in just_run
    return loop.run_until_complete(coro)
  File "C:\Users\User\anaconda3\lib\asyncio\base_events.py", line 647, in run_until_complete
    return future.result()
  File "C:\Users\User\anaconda3\lib\site-packages\nbclient\client.py", line 663, in async_execute
    await self.async_execute_cell(
  File "C:\Users\User\anaconda3\lib\site-packages\nbclient\client.py", line 965, in async_execute_cell
    await self._check_raise_for_error(cell, cell_index, exec_reply)
  File "C:\Users\User\anaconda3\lib\site-packages\nbclient\client.py", line 862, in _check_raise_for_error
    raise CellExecutionError.from_cell_and_msg(cell, exec_reply_content)
nbclient.exceptions.CellExecutionError: An error occurred while executing the following cell:
------------------
# load GrowthData
rdata_read = pyreadr.read_r("../data/GrowthData.RData")
GrowthData = rdata_read[ 'GrowthData' ]
n = GrowthData.shape[0]
------------------

[1;31m---------------------------------------------------------------------------[0m
[1;31mPyreadrError[0m                              Traceback (most recent call last)
Input [1;32mIn [5][0m, in [0;36m<cell line: 2>[1;34m()[0m
[0;32m      1[0m [38;5;66;03m# load GrowthData[39;00m
[1;32m----> 2[0m rdata_read [38;5;241m=[39m [43mpyreadr[49m[38;5;241;43m.[39;49m[43mread_r[49m[43m([49m[38;5;124;43m"[39;49m[38;5;124;43m../data/GrowthData.RData[39;49m[38;5;124;43m"[39;49m[43m)[49m
[0;32m      3[0m GrowthData [38;5;241m=[39m rdata_read[ [38;5;124m'[39m[38;5;124mGrowthData[39m[38;5;124m'[39m ]
[0;32m      4[0m n [38;5;241m=[39m GrowthData[38;5;241m.[39mshape[[38;5;241m0[39m]

File [1;32m~\anaconda3\lib\site-packages\pyreadr\pyreadr.py:65[0m, in [0;36mread_r[1;34m(path, use_objects, timezone)[0m
[0;32m     63[0m filename_bytes [38;5;241m=[39m os[38;5;241m.[39mpath[38;5;241m.[39mexpanduser(filename_bytes)
[0;32m     64[0m [38;5;28;01mif[39;00m [38;5;129;01mnot[39;00m os[38;5;241m.[39mpath[38;5;241m.[39misfile(filename_bytes):
[1;32m---> 65[0m     [38;5;28;01mraise[39;00m PyreadrError([38;5;124m"[39m[38;5;124mFile [39m[38;5;132;01m{0}[39;00m[38;5;124m does not exist![39m[38;5;124m"[39m[38;5;241m.[39mformat(filename_bytes))
[0;32m     66[0m parser[38;5;241m.[39mparse(filename_bytes)
[0;32m     68[0m result [38;5;241m=[39m OrderedDict()

[1;31mPyreadrError[0m: File b'../data/GrowthData.RData' does not exist!
PyreadrError: File b'../data/GrowthData.RData' does not exist!

