Traceback (most recent call last):
  File "C:\Users\User\anaconda3\lib\site-packages\jupyter_cache\executors\utils.py", line 51, in single_nb_execution
    executenb(
  File "C:\Users\User\anaconda3\lib\site-packages\nbclient\client.py", line 1204, in execute
    return NotebookClient(nb=nb, resources=resources, km=km, **kwargs).execute()
  File "C:\Users\User\anaconda3\lib\site-packages\nbclient\util.py", line 84, in wrapped
    return just_run(coro(*args, **kwargs))
  File "C:\Users\User\anaconda3\lib\site-packages\nbclient\util.py", line 62, in just_run
    return loop.run_until_complete(coro)
  File "C:\Users\User\anaconda3\lib\asyncio\base_events.py", line 647, in run_until_complete
    return future.result()
  File "C:\Users\User\anaconda3\lib\site-packages\nbclient\client.py", line 663, in async_execute
    await self.async_execute_cell(
  File "C:\Users\User\anaconda3\lib\site-packages\nbclient\client.py", line 965, in async_execute_cell
    await self._check_raise_for_error(cell, cell_index, exec_reply)
  File "C:\Users\User\anaconda3\lib\site-packages\nbclient\client.py", line 862, in _check_raise_for_error
    raise CellExecutionError.from_cell_and_msg(cell, exec_reply_content)
nbclient.exceptions.CellExecutionError: An error occurred while executing the following cell:
------------------
table2 = np.zeros((2, 4))
table2[0,0] = ols_cl.summary2().tables[1]['Coef.']['T4']
table2[0,1] = ols_cra.summary2().tables[1]['Coef.']['T4TRUE']
table2[0,2] = ols_ira.summary2().tables[1]['Coef.']['T4']
table2[0,3] = rlasso_ira['Coef.']['T4']

table2[1,0] = ols_cl.summary2().tables[1]['Std.Err.']['T4']
table2[1,1] = ols_cra.summary2().tables[1]['Std.Err.']['T4TRUE']
table2[1,2] = ols_ira.summary2().tables[1]['Std.Err.']['T4']
table2[1,3] = rlasso_ira['Std.Err.']['T4']

table2 = pd.DataFrame(table2, columns = ["$CL$", "$CRA$", "$IRA$", "$IRA Lasso$"], \
                      index = ["estimate","standard error"])
table2
------------------

[1;31m---------------------------------------------------------------------------[0m
[1;31mKeyError[0m                                  Traceback (most recent call last)
File [1;32m~\anaconda3\lib\site-packages\pandas\core\indexes\base.py:3621[0m, in [0;36mIndex.get_loc[1;34m(self, key, method, tolerance)[0m
[0;32m   3620[0m [38;5;28;01mtry[39;00m:
[1;32m-> 3621[0m     [38;5;28;01mreturn[39;00m [38;5;28;43mself[39;49m[38;5;241;43m.[39;49m[43m_engine[49m[38;5;241;43m.[39;49m[43mget_loc[49m[43m([49m[43mcasted_key[49m[43m)[49m
[0;32m   3622[0m [38;5;28;01mexcept[39;00m [38;5;167;01mKeyError[39;00m [38;5;28;01mas[39;00m err:

File [1;32m~\anaconda3\lib\site-packages\pandas\_libs\index.pyx:136[0m, in [0;36mpandas._libs.index.IndexEngine.get_loc[1;34m()[0m

File [1;32m~\anaconda3\lib\site-packages\pandas\_libs\index.pyx:163[0m, in [0;36mpandas._libs.index.IndexEngine.get_loc[1;34m()[0m

File [1;32mpandas\_libs\hashtable_class_helper.pxi:5198[0m, in [0;36mpandas._libs.hashtable.PyObjectHashTable.get_item[1;34m()[0m

File [1;32mpandas\_libs\hashtable_class_helper.pxi:5206[0m, in [0;36mpandas._libs.hashtable.PyObjectHashTable.get_item[1;34m()[0m

[1;31mKeyError[0m: 'T4'

The above exception was the direct cause of the following exception:

[1;31mKeyError[0m                                  Traceback (most recent call last)
Input [1;32mIn [16][0m, in [0;36m<cell line: 4>[1;34m()[0m
[0;32m      2[0m table2[[38;5;241m0[39m,[38;5;241m0[39m] [38;5;241m=[39m ols_cl[38;5;241m.[39msummary2()[38;5;241m.[39mtables[[38;5;241m1[39m][[38;5;124m'[39m[38;5;124mCoef.[39m[38;5;124m'[39m][[38;5;124m'[39m[38;5;124mT4[39m[38;5;124m'[39m]
[0;32m      3[0m table2[[38;5;241m0[39m,[38;5;241m1[39m] [38;5;241m=[39m ols_cra[38;5;241m.[39msummary2()[38;5;241m.[39mtables[[38;5;241m1[39m][[38;5;124m'[39m[38;5;124mCoef.[39m[38;5;124m'[39m][[38;5;124m'[39m[38;5;124mT4TRUE[39m[38;5;124m'[39m]
[1;32m----> 4[0m table2[[38;5;241m0[39m,[38;5;241m2[39m] [38;5;241m=[39m [43mols_ira[49m[38;5;241;43m.[39;49m[43msummary2[49m[43m([49m[43m)[49m[38;5;241;43m.[39;49m[43mtables[49m[43m[[49m[38;5;241;43m1[39;49m[43m][49m[43m[[49m[38;5;124;43m'[39;49m[38;5;124;43mCoef.[39;49m[38;5;124;43m'[39;49m[43m][49m[43m[[49m[38;5;124;43m'[39;49m[38;5;124;43mT4[39;49m[38;5;124;43m'[39;49m[43m][49m
[0;32m      5[0m table2[[38;5;241m0[39m,[38;5;241m3[39m] [38;5;241m=[39m rlasso_ira[[38;5;124m'[39m[38;5;124mCoef.[39m[38;5;124m'[39m][[38;5;124m'[39m[38;5;124mT4[39m[38;5;124m'[39m]
[0;32m      7[0m table2[[38;5;241m1[39m,[38;5;241m0[39m] [38;5;241m=[39m ols_cl[38;5;241m.[39msummary2()[38;5;241m.[39mtables[[38;5;241m1[39m][[38;5;124m'[39m[38;5;124mStd.Err.[39m[38;5;124m'[39m][[38;5;124m'[39m[38;5;124mT4[39m[38;5;124m'[39m]

File [1;32m~\anaconda3\lib\site-packages\pandas\core\series.py:958[0m, in [0;36mSeries.__getitem__[1;34m(self, key)[0m
[0;32m    955[0m     [38;5;28;01mreturn[39;00m [38;5;28mself[39m[38;5;241m.[39m_values[key]
[0;32m    957[0m [38;5;28;01melif[39;00m key_is_scalar:
[1;32m--> 958[0m     [38;5;28;01mreturn[39;00m [38;5;28;43mself[39;49m[38;5;241;43m.[39;49m[43m_get_value[49m[43m([49m[43mkey[49m[43m)[49m
[0;32m    960[0m [38;5;28;01mif[39;00m is_hashable(key):
[0;32m    961[0m     [38;5;66;03m# Otherwise index.get_value will raise InvalidIndexError[39;00m
[0;32m    962[0m     [38;5;28;01mtry[39;00m:
[0;32m    963[0m         [38;5;66;03m# For labels that don't resolve as scalars like tuples and frozensets[39;00m

File [1;32m~\anaconda3\lib\site-packages\pandas\core\series.py:1069[0m, in [0;36mSeries._get_value[1;34m(self, label, takeable)[0m
[0;32m   1066[0m     [38;5;28;01mreturn[39;00m [38;5;28mself[39m[38;5;241m.[39m_values[label]
[0;32m   1068[0m [38;5;66;03m# Similar to Index.get_value, but we do not fall back to positional[39;00m
[1;32m-> 1069[0m loc [38;5;241m=[39m [38;5;28;43mself[39;49m[38;5;241;43m.[39;49m[43mindex[49m[38;5;241;43m.[39;49m[43mget_loc[49m[43m([49m[43mlabel[49m[43m)[49m
[0;32m   1070[0m [38;5;28;01mreturn[39;00m [38;5;28mself[39m[38;5;241m.[39mindex[38;5;241m.[39m_get_values_for_loc([38;5;28mself[39m, loc, label)

File [1;32m~\anaconda3\lib\site-packages\pandas\core\indexes\base.py:3623[0m, in [0;36mIndex.get_loc[1;34m(self, key, method, tolerance)[0m
[0;32m   3621[0m     [38;5;28;01mreturn[39;00m [38;5;28mself[39m[38;5;241m.[39m_engine[38;5;241m.[39mget_loc(casted_key)
[0;32m   3622[0m [38;5;28;01mexcept[39;00m [38;5;167;01mKeyError[39;00m [38;5;28;01mas[39;00m err:
[1;32m-> 3623[0m     [38;5;28;01mraise[39;00m [38;5;167;01mKeyError[39;00m(key) [38;5;28;01mfrom[39;00m [38;5;21;01merr[39;00m
[0;32m   3624[0m [38;5;28;01mexcept[39;00m [38;5;167;01mTypeError[39;00m:
[0;32m   3625[0m     [38;5;66;03m# If we have a listlike key, _check_indexing_error will raise[39;00m
[0;32m   3626[0m     [38;5;66;03m#  InvalidIndexError. Otherwise we fall through and re-raise[39;00m
[0;32m   3627[0m     [38;5;66;03m#  the TypeError.[39;00m
[0;32m   3628[0m     [38;5;28mself[39m[38;5;241m.[39m_check_indexing_error(key)

[1;31mKeyError[0m: 'T4'
KeyError: 'T4'

