Traceback (most recent call last):
  File "C:\Users\User\anaconda3\lib\site-packages\jupyter_cache\executors\utils.py", line 51, in single_nb_execution
    executenb(
  File "C:\Users\User\anaconda3\lib\site-packages\nbclient\client.py", line 1204, in execute
    return NotebookClient(nb=nb, resources=resources, km=km, **kwargs).execute()
  File "C:\Users\User\anaconda3\lib\site-packages\nbclient\util.py", line 84, in wrapped
    return just_run(coro(*args, **kwargs))
  File "C:\Users\User\anaconda3\lib\site-packages\nbclient\util.py", line 62, in just_run
    return loop.run_until_complete(coro)
  File "C:\Users\User\anaconda3\lib\asyncio\base_events.py", line 647, in run_until_complete
    return future.result()
  File "C:\Users\User\anaconda3\lib\site-packages\nbclient\client.py", line 663, in async_execute
    await self.async_execute_cell(
  File "C:\Users\User\anaconda3\lib\site-packages\nbclient\client.py", line 965, in async_execute_cell
    await self._check_raise_for_error(cell, cell_index, exec_reply)
  File "C:\Users\User\anaconda3\lib\site-packages\nbclient\client.py", line 862, in _check_raise_for_error
    raise CellExecutionError.from_cell_and_msg(cell, exec_reply_content)
nbclient.exceptions.CellExecutionError: An error occurred while executing the following cell:
------------------
import numpy as np
import pandas as pd
import doubleml as dml
from doubleml.datasets import fetch_401K

from sklearn.preprocessing import PolynomialFeatures
from sklearn.linear_model import LassoCV, LogisticRegressionCV
from sklearn.ensemble import RandomForestClassifier, RandomForestRegressor
from sklearn.tree import DecisionTreeClassifier, DecisionTreeRegressor
from sklearn.preprocessing import StandardScaler
from sklearn.pipeline import make_pipeline

from xgboost import XGBClassifier, XGBRegressor

import matplotlib.pyplot as plt
import seaborn as sns
import hdmpy
import pyreadr
import warnings
warnings.filterwarnings('ignore')
------------------

[1;31m---------------------------------------------------------------------------[0m
[1;31mModuleNotFoundError[0m                       Traceback (most recent call last)
Input [1;32mIn [1][0m, in [0;36m<cell line: 3>[1;34m()[0m
[0;32m      1[0m [38;5;28;01mimport[39;00m [38;5;21;01mnumpy[39;00m [38;5;28;01mas[39;00m [38;5;21;01mnp[39;00m
[0;32m      2[0m [38;5;28;01mimport[39;00m [38;5;21;01mpandas[39;00m [38;5;28;01mas[39;00m [38;5;21;01mpd[39;00m
[1;32m----> 3[0m [38;5;28;01mimport[39;00m [38;5;21;01mdoubleml[39;00m [38;5;28;01mas[39;00m [38;5;21;01mdml[39;00m
[0;32m      4[0m [38;5;28;01mfrom[39;00m [38;5;21;01mdoubleml[39;00m[38;5;21;01m.[39;00m[38;5;21;01mdatasets[39;00m [38;5;28;01mimport[39;00m fetch_401K
[0;32m      6[0m [38;5;28;01mfrom[39;00m [38;5;21;01msklearn[39;00m[38;5;21;01m.[39;00m[38;5;21;01mpreprocessing[39;00m [38;5;28;01mimport[39;00m PolynomialFeatures

[1;31mModuleNotFoundError[0m: No module named 'doubleml'
ModuleNotFoundError: No module named 'doubleml'

